<mujoco model="6Modules-Snake">
    <compiler angle="degree" coordinate="local" inertiafromgeom="true"/>
    <option integrator="Euler" timestep="0.0125">
        <flag energy="enable" clampctrl="enable"/>
    </option>
    <size nconmax="1000"/>

    <!--  ================= old 6Modules-Snake.xml ================= /-->
    <!--
    <compiler angle="radian" />
    <size njmax="500" nconmax="100" />
    -->

    <!--  ================= defaults ================= /-->
    <default>
        <!-- for power effizient experiment-->
        <!-- 600-->
        <geom conaffinity="0" condim="3" friction="1 0.05 0.00001" margin="0.01" density="600" />
        <joint armature='0.001' damping="0" frictionloss="0.001" />
        <!-- armature='1' damping="1" -->
        <!--
          <default class="back">
              <geom fromto="0 0 0 -0.5 0 0" size="0.1" type="capsule"/>
              <joint pos="0 0 0" limited="true" type="hinge"/>
          </default>
        -->

        <!--
        forcerange: Range for clamping the force output. more strength, more acceleration to get to the position
        kp: servo gain, Position feedback gain
        stiffness: (also known as proportional gain) 400, 300
        damping: (also known as derivative gain), and feedback gain, absorb vibration energy
        gear: scales the length (and consequently moment arms, velocity and force),
        frictionloss: Friction loss due to dry friction/static friction
        density: volume*mass, resulting in the weight depending on the model size
        armature: Armature inertia (or rotor inertia)

        ctrlrange: looks like with 90d it can move between [-1.5, 1.5] TODO not [-2.0, 2.0]?
        <position ctrllimited="true" ctrlrange="-1.5 1.5" forcelimited="true" forcerange="-40.0 40.0" kp="50" gear="1"/>
        <position ctrllimited="true" ctrlrange="-1.5 1.5" forcelimited="true" forcerange="-20.0 20.0" kp="10" gear="1"/>

        <position ctrllimited="true" ctrlrange="-1.5 1.5" forcelimited="true" forcerange="-40.0 40.0" kp="15" gear="0.175"/>
        -->
        <position ctrllimited="true" ctrlrange="-1.5 1.5" forcelimited="true" forcerange="-10.0 10.0" kp="7" gear="1"/>

    </default>

    <asset>
        <mesh name="Tail" file="Tail.STL" />
        <mesh name="Module_1" file="Module_1.STL" />
        <mesh name="Module_2" file="Module_2.STL" />
        <mesh name="Module_3" file="Module_3.STL" />
        <mesh name="Module_4" file="Module_4.STL" />
        <mesh name="Module_5" file="Module_5.STL" />
        <mesh name="Head" file="Head.STL" />


        <!-- My Textures -->
        <!--  ================= Target Mesh ================= /-->
        <texture builtin="gradient" height="100" rgb1="1 1 1" rgb2="0 0 0" type="skybox" width="100"/>
        <texture builtin="flat" height="1278" mark="cross" markrgb="1 1 1" name="texgeom" random="0.01"
                 rgb1="0.8 0.6 0.4" rgb2="0.8 0.6 0.4" type="cube" width="127"/>
        <texture builtin="checker" height="100" name="texplane" rgb1="0 0 0" rgb2="0.8 0.8 0.8" type="2d" width="100"/>
        <material name="MatPlane" reflectance="0.5" shininess="1" specular="1" texrepeat="80 80" texture="texplane"/>
        <!-- 80 80 is one le -->
        <material name="geom" texture="texgeom" texuniform="true"/>

        <!--
        <texture name="TexGrass" file="grass3.png" type="2d" />
        <material name="MatGrass" reflectance="0.05" shininess="0.1" specular="0.1" texrepeat="25 25" texture="TexGrass"/>
        -->
        <material name="MatTarget" rgba="1 0 0 1" reflectance="0.05" shininess="0.1" specular="0.1"/>
    </asset>

    <!-- Add manually-->
    <visual>
        <map znear="0.0625"  />
        <!--
        <map znear="0.0625"  />
        <map znear="0.075"  />
        <map znear="0.08"  />

        <scale />
        <global fovy="90" glow="0"/>
        <headlight ambient="1 1 1" diffuse="0 0 0" specular="0 0 0"/>
        <headlight ambient=".4 .4 .4" diffuse=".8 .8 .8" specular="0.1 0.1 0.1"/>
        <quality shadowsize="4096"/>

         for plots
        <quality shadowsize="16384"/>
        -->
        <quality shadowsize="4096"/>

    </visual>


    <worldbody>
        <light cutoff="100" diffuse="1 1 1" dir="-0 0 -1.3" directional="true" exponent="1" pos="0 0 1.3"
               specular=".1 .1 .1"/>
        <!-- <geom conaffinity="1" condim="3" material="MatPlane" name="floor" pos="0 0 -0.1" rgba="0.8 0.9 0.8 1" size="40 40 40" type="plane"/>-->
        <geom name="floor" size="80 80 10" material="MatPlane" conaffinity="1" condim="3" pos="0 0 -0.025" rgba="0.8 0.9 0.8 0.71" type="plane"/>

        <!--  ================= Sun ================= /-->
        <!--
        <body name="sun" pos="0 -4 5">
            <light pos="0 0 0" mode="trackcom" directional="false"/>
            <joint axis="1 0 0" name="sun_slider_x" type="slide"/>
            <joint axis="0 1 0" name="sun_slider_y" type="slide"/>
            <geom type="sphere" size="1" material="MatTarget" rgba="1.0 1.0 0.0 1"/>
        </body>
        -->

        <!--  ================= Target ================= /-->
        <!-- <body name="target_ball" pos="0 0 0.1"> -->
        <body name="target_ball" pos="0.2 0.0 0.05">
            <joint axis="1 0 0" name="target_slider_x" type="slide"/>
            <joint axis="0 1 0" name="target_slider_y" type="slide"/>
            <geom name="target_ball_geom" type="sphere" pos="0 0 0" size="0.05" material="MatTarget"/>
            <camera name="track_ball" mode="trackcom" pos="0 -4 6" euler="30 0 0"/>
            <camera name="track_ball2" mode="targetbodycom" pos="0 0 1" zaxis="0 0 90" />
        </body>


        <!--  ================= Add manually ================= /-->
        <body name="Snake-bodys" pos="-0.45 -0.01  0">

        <!--  ================= Add manually ================= /-->
        <!--
        <geom name="head" pos="0.0675 0 .01" size=".01 .02 .01" type="box" rgba="0.8 0.7 .6 1"/>
        <site name='site_head' pos='0.0675 0 0.0' type='box'  size='.01 .01 .01'/>
        -->
        <!-- <camera name="head" mode="fixed" pos="0 0 0.02" fovy="90" euler="90 -90 0"/> -->

        <!--
        <geom name="head" pos="0 .0 .02" type="box" size=".01 .01 .01" rgba="1 0 0 0.6"/>
        <site name='site_head' pos='0 0 0.01' type='box'  size='.01 .01 .01' rgba="0 0 1 0.9"/>
        <camera name="head" pos="0 0 0.02" fovy="90" euler="90 -90 0"/>

       <joint pos=".01 0 0" axis="1 0 0" name="slider_x" type="slide"/>
       <joint pos=".01 0 0" axis="0 1 0" name="slider_y" type="slide"/>
       <joint pos=".01 0 0" axis="0 0 1" name="slider_z" type="slide"/>

       <joint pos=".01 0 0" axis="1 0 0" name="hinge_x" type="hinge"/>
       <joint pos=".01 0 0" axis="0 1 0" name="hinge_y" type="hinge"/>
       <joint pos=".01 0 0" axis="0 0 1" name="hinge_z" type="hinge"/>


        <geom type="mesh" rgba="0.79216 0.81961 0.93333 1" mesh="Tail" />
        <body name="Module_1" pos="0.0398 0.0145 0.043">
            <inertial pos="0.15843 0.00036206 -0.023661" quat="0.268962 0.65397 0.269933 0.653543" mass="0.34605" diaginertia="0.00569944 0.00569937 7.43933e-05" />
            <joint name="Joint_1" pos="0 0 0" axis="0 0 1" limited="true" range="-90 90" damping="5" frictionloss="20" />
            <geom type="mesh" rgba="0.79216 0.81961 0.93333 1" mesh="Module_1" />
            <body name="Module_2" pos="0.0675 0 -0.024">
        -->




            <!--  ====== copy from "6Modules-Feb17-v2-edited.xml" ====== -->
            <geom type="mesh" rgba="0.79216 0.81961 0.93333 1" mesh="Tail" />
            <body name="Module_1" pos="0.0398 0.0145 0.043">
                <inertial pos="0.15843 0.00036206 -0.023661" quat="0.268962 0.65397 0.269933 0.653543" mass="0.34605" diaginertia="0.00569944 0.00569937 7.43933e-05" />
                <joint name="Joint_1" pos="0 0 0" axis="0 0 1" limited="true" range="-90 90" damping="5" frictionloss="20" />
                <geom type="mesh" rgba="0.79216 0.81961 0.93333 1" mesh="Module_1" />
                <body name="Module_2" pos="0.0675 0 -0.024">
                    <inertial pos="0.090932 0.00036206 0.00033889" quat="0.268962 0.65397 0.269933 0.653543" mass="0.34605" diaginertia="0.00569944 0.00569937 7.43933e-05" />
                    <joint name="Joint_2" pos="0 0 0" axis="0 -1 0" limited="true" range="-9 9" damping="5" frictionloss="20" />
                    <geom type="mesh" rgba="0.79216 0.81961 0.93333 1" mesh="Module_2" />
                    <body name="Module_3" pos="0.0675 0 0">
                        <inertial pos="0.023432 0.00036206 0.00033889" quat="0.268962 0.65397 0.269933 0.653543" mass="0.34605" diaginertia="0.00569944 0.00569937 7.43933e-05" />
                        <joint name="Joint_3" pos="0 0 0" axis="0 0 1" limited="true" range="-90 90" damping="5" frictionloss="20" />
                        <geom type="mesh" rgba="0.79216 0.81961 0.93333 1" mesh="Module_3" />
                        <body name="Module_4" pos="0.0675 0 0">
                            <inertial pos="-0.044068 0.00036206 0.00033889" quat="0.268962 0.65397 0.269933 0.653543" mass="0.34605" diaginertia="0.00569944 0.00569937 7.43933e-05" />
                            <joint name="Joint_4" pos="0 0 0" axis="0 -1 0" limited="true" range="-9 9" damping="5" frictionloss="20" />
                            <geom type="mesh" rgba="0.79216 0.81961 0.93333 1" mesh="Module_4" />
                            <body name="Module_5" pos="0.0675 0 0">
                                <inertial pos="-0.11157 0.00036206 0.00033889" quat="0.268962 0.65397 0.269933 0.653543" mass="0.34605" diaginertia="0.00569944 0.00569937 7.43933e-05" />
                                <joint name="Joint_5" pos="0 0 0" axis="0 0 1" limited="true" range="-90 90" damping="5" frictionloss="20" />
                                <geom type="mesh" rgba="0.79216 0.81961 0.93333 1" mesh="Module_5" />
                                <body name="Head" pos="0.0675 0 0">
                                    <inertial pos="-0.17907 0.00036206 0.00033889" quat="0.268962 0.65397 0.269933 0.653543" mass="0.34605" diaginertia="0.00569944 0.00569937 7.43933e-05" />
                                    <joint name="Joint_Head" pos="0 0 0" axis="0 1 0" limited="true" range="-9 9" damping="5" frictionloss="20" />
                                    <geom type="mesh" rgba="0.79216 0.81961 0.93333 1" mesh="Head" />


                                    <!--  ================= Add manually ================= /-->
                                    <body name="front" pos="0.0675 0 0">
                                        <geom name="front_head" pos="0 0 .02" type="box" size=".01 .01 .01" rgba="1 0 0 0.6"/>
                                        <camera name="cam_head" pos="0 0 .02" fovy="90" euler="90 -90 0"/>
                                        <site name="site_head" pos="0 0 .02" type="box"  size=".01 .01 .01" rgba="0 0 1 0.9"/>

                                    <!--
                                    <geom name="head" pos=".05 .0 .02" type="box" size=".01 .01 .01" rgba="1 0 0 0.6"/>
                                    <site name='site_head' pos='.05 0 0.02' type='box'  size='.01 .01 .01' rgba="0 0 1 0.9"/>
                                    <camera name="head" pos=".05 0 0.02" fovy="90" euler="90 -90 0"/>

                                    <joint pos=".01 0 0" axis="1 0 0" name="slider_x" type="slide"/>
                                    <joint pos=".01 0 0" axis="0 1 0" name="slider_y" type="slide"/>
                                    <joint pos=".01 0 0" axis="0 0 1" name="slider_z" type="slide"/>

                                    <joint pos=".01 0 0" axis="1 0 0" name="hinge_x" type="hinge"/>
                                    <joint pos=".01 0 0" axis="0 1 0" name="hinge_y" type="hinge"/>
                                    <joint pos=".01 0 0" axis="0 0 1" name="hinge_z" type="hinge"/>

                                    <geom name="head" pos=".05 .0 .02" type="box" size=".01 .01 .01" rgba="1 0 0 0.6"/>
                                    <site name='site_head' pos='.05 0 0.01' type='box'  size='.01 .01 .01' rgba="0 0 1 0.9"/>
                                    <camera name="head" pos=".05 0 0.02" fovy="90" euler="90 -90 0"/>
                                    -->
                                    </body>
                                </body>
                            </body>
                        </body>
                    </body>
                </body>
            </body>

            <joint pos=".01 0 0" axis="1 0 0" name="slider_x" type="slide"/>
            <joint pos=".01 0 0" axis="0 1 0" name="slider_y" type="slide"/>
            <joint pos=".01 0 0" axis="0 0 1" name="slider_z" type="slide"/>

            <joint pos=".01 0 0" axis="1 0 0" name="hinge_x" type="hinge"/>
            <joint pos=".01 0 0" axis="0 1 0" name="hinge_y" type="hinge"/>
            <joint pos=".01 0 0" axis="0 0 1" name="hinge_z" type="hinge"/>
            <!--  ================= Add manually ================= /-->
    </body>

    </worldbody>



    <actuator >
        <!--
        <motor joint="joint01"/>
        <motor joint="joint02"/>
        <motor joint="joint03"/>
        <motor joint="joint04"/>
        <motor joint="joint05"/>
        <motor joint="joint06"/>
        <motor joint="joint07"/>
        <motor joint="joint08"/>

        <position name="actuator_joint01" joint="Joint_Head"/>
        <position name="actuator_joint02" joint="Joint_5"/>
        <position name="actuator_joint03" joint="Joint_4"/>
        <position name="actuator_joint04" joint="Joint_3"/>
        <position name="actuator_joint05" joint="Joint_2"/>
        <position name="actuator_joint06" joint="Joint_1"/>
        -->

        <position name="actuator_joint01" joint="Joint_1"/>
        <position name="actuator_joint02" joint="Joint_2"/>
        <position name="actuator_joint03" joint="Joint_3"/>
        <position name="actuator_joint04" joint="Joint_4"/>
        <position name="actuator_joint05" joint="Joint_5"/>
        <position name="actuator_joint06" joint="Joint_Head"/>

    </actuator>
    <sensor>
        <!--
        <jointpos name="sensor_jointpos_joint01" joint="joint01" />
        <jointvel name="sensor_jointvel_joint01" joint="joint01" />
        -->

        <actuatorfrc name="sensor_actuatorfrc_joint01" actuator="actuator_joint01" />
        <actuatorfrc name="sensor_actuatorfrc_joint02" actuator="actuator_joint02" />
        <actuatorfrc name="sensor_actuatorfrc_joint03" actuator="actuator_joint03" />
        <actuatorfrc name="sensor_actuatorfrc_joint04" actuator="actuator_joint04" />
        <actuatorfrc name="sensor_actuatorfrc_joint05" actuator="actuator_joint05" />
        <actuatorfrc name="sensor_actuatorfrc_joint06" actuator="actuator_joint06" />

        <velocimeter name="sensor_velocimeter" site="site_head"/>
        <accelerometer name="sensor_accelerometer" site="site_head"/>

    </sensor>
</mujoco>
