<mujoco model="6Modules-Snake">
<!--    <compiler angle="radian" coordinate="local" inertiafromgeom="true"/>-->
    <compiler angle="degree" coordinate="local" inertiafromgeom="true"/>
    <option integrator="Euler" timestep="0.0125">
<!--    <option integrator="RK4" timestep="0.01">-->
        <flag energy="enable" clampctrl="enable"/>
    </option>
    <size nconmax="1000"/>

    <!--  ================= old 6Modules-Snake.xml ================= /-->
    <!--
    <compiler angle="radian" />
    <size njmax="500" nconmax="100" />
    -->

    <!--  ================= defaults ================= /-->
    <default>
        <!-- for power effizient experiment-->
        <!-- 600-->
<!--        <geom conaffinity="0" condim="3" friction="1 0.05 0.00001" margin="0.01" density="800" />-->
<!--        <joint armature='1' damping="0.1" frictionloss="0.01" />-->
<!--        <joint armature='0.001' damping="0" frictionloss="0.001" />-->
        <!-- armature='1' damping="1" -->
        <!--
          <default class="back">
              <geom fromto="0 0 0 -0.5 0 0" size="0.1" type="capsule"/>
              <joint pos="0 0 0" limited="true" type="hinge"/>
          </default>
        -->

        <!--
        forcerange: Range for clamping the force output. more strength, more acceleration to get to the position
        kp: servo gain, Position feedback gain
        stiffness: (also known as proportional gain) 400, 300
        damping: (also known as derivative gain), and feedback gain, absorb vibration energy
        gear: scales the length (and consequently moment arms, velocity and force),
        frictionloss: Friction loss due to dry friction/static friction
        density: volume*mass, resulting in the weight depending on the model size
        armature: Armature inertia (or rotor inertia)

        ctrlrange: looks like with 90d it can move between [-1.5, 1.5] TODO not [-2.0, 2.0]?
        <position ctrllimited="true" ctrlrange="-1.5 1.5" forcelimited="true" forcerange="-40.0 40.0" kp="50" gear="1"/>
        <position ctrllimited="true" ctrlrange="-1.5 1.5" forcelimited="true" forcerange="-40.0 40.0" kp="15" gear="0.175"/>
        -->

        <default class="snakeBody_class">
            <geom conaffinity="1" condim="3" friction="1 0.95 0.00001" material="MatBody"/>
            <joint armature='0.001' damping="0" frictionloss="0.001" />
        </default>

        <!-- TODO 对于 test_M1_simple_7Modules 模型，以下参数能使蛇稳定向前移动  -->
        <position ctrllimited="true" ctrlrange="-1.5 1.5" forcelimited="true" forcerange="-50.0 50.0" kp="15" gear="1"/>
    </default>

    <asset>
        <material name="MatBody" specular="3" shininess=".5" reflectance="1" rgba=".3 .4 .35 1"/>

<!--        <mesh name="Tail" file="Tail.STL" />-->
<!--        <mesh name="Module_1" file="Module_1.STL" />-->
<!--        <mesh name="Module_2" file="Module_2.STL" />-->
<!--        <mesh name="Module_3" file="Module_3.STL" />-->
<!--        <mesh name="Module_4" file="Module_4.STL" />-->
<!--        <mesh name="Module_5" file="Module_5.STL" />-->
<!--        <mesh name="Head" file="Head.STL" />-->


        <!-- My Textures -->
        <!--  ================= Target Mesh ================= /-->
        <texture builtin="gradient" height="100" rgb1="1 1 1" rgb2="0 0 0" type="skybox" width="100"/>
        <texture builtin="flat" height="1278" mark="cross" markrgb="1 1 1" name="texgeom" random="0.01"
                 rgb1="0.8 0.6 0.4" rgb2="0.8 0.6 0.4" type="cube" width="127"/>
        <texture builtin="checker" height="100" name="texplane" rgb1="0 0 0" rgb2="0.8 0.8 0.8" type="2d" width="100"/>
        <material name="MatPlane" reflectance="0.5" shininess="1" specular="1" texrepeat="80 80" texture="texplane"/>
        <!-- 80 80 is one le -->
        <material name="geom" texture="texgeom" texuniform="true"/>

        <!--
        <texture name="TexGrass" file="grass3.png" type="2d" />
        <material name="MatGrass" reflectance="0.05" shininess="0.1" specular="0.1" texrepeat="25 25" texture="TexGrass"/>
        -->
        <material name="MatTarget" rgba="1 0 0 1" reflectance="0.05" shininess="0.1" specular="0.1"/>
    </asset>

    <!-- Add manually-->
    <visual>
        <map znear="0.0625"  />
        <!--
        <map znear="0.0625"  />
        <map znear="0.075"  />
        <map znear="0.08"  />

        <scale />
        <global fovy="90" glow="0"/>
        <headlight ambient="1 1 1" diffuse="0 0 0" specular="0 0 0"/>
        <headlight ambient=".4 .4 .4" diffuse=".8 .8 .8" specular="0.1 0.1 0.1"/>
        <quality shadowsize="4096"/>

         for plots
        <quality shadowsize="16384"/>
        -->
        <quality shadowsize="4096"/>

    </visual>


    <worldbody>
        <light cutoff="100" diffuse="1 1 1" dir="-0 0 -1.3" directional="true" exponent="1" pos="0 0 1.3"
               specular=".1 .1 .1"/>
        <!-- <geom conaffinity="1" condim="3" material="MatPlane" name="floor" pos="0 0 -0.1" rgba="0.8 0.9 0.8 1" size="40 40 40" type="plane"/>-->
        <geom name="floor" size="80 80 10" material="MatPlane" conaffinity="1" condim="3" pos="0 0 -0.025" rgba="0.8 0.9 0.8 0.71" type="plane"/>

        <!--  ================= Sun ================= /-->
        <!--
        <body name="sun" pos="0 -4 5">
            <light pos="0 0 0" mode="trackcom" directional="false"/>
            <joint axis="1 0 0" name="sun_slider_x" type="slide"/>
            <joint axis="0 1 0" name="sun_slider_y" type="slide"/>
            <geom type="sphere" size="1" material="MatTarget" rgba="1.0 1.0 0.0 1"/>
        </body>
        -->

        <!--  ================= Target ================= /-->
        <body name="target_ball" pos="-1 0.0 0.05">
            <joint axis="1 0 0" name="target_slider_x" type="slide"/>
            <joint axis="0 1 0" name="target_slider_y" type="slide"/>
            <geom name="target_ball_geom" type="sphere" pos="0 0 0.08" size="0.05" rgba="1 0 0 1"/>
        </body>


        <!--  ================= Add manually ================= /-->
        <body name="Snake-bodys" pos="0 0 .04" childclass="snakeBody_class">
            <!-- Simulate the firctional sliding on the floor -->
            <geom name="front_head" pos="-0.05 0.015 .025" type="box" size=".01 .01 .01" rgba="1 0 0 0.6"/>
            <camera name="cam_head" pos="-0.05 0.0 .065" fovy="90" euler="90 -90 0"/>
            <site name="site_head" pos="-0.05 0.0 .065" type="box"  size=".03 .03 .03" rgba="1 0 1 0.9"/>

            <site name="eyeL" type="sphere" size="0.02" pos="-.065 -.045 .02" rgba=".9 .4 .2 1"/>
            <site name="eyer" type="sphere" size="0.02" pos="-.065 0.045 .02" rgba=".9 .4 .2 1"/>
            <site name="head" material="MatBody" type="sphere" size="0.08" pos="0 0 0.04" rgba="0 0 0 1"/>
<!--            <inertial pos="0 0 0" quat="0.707 0 -0.707 0" mass="2.749" diaginertia="0.03 0.03 0.001"/>-->

            <geom type="capsule" pos="0.2 0 .04" quat="0.707 0 -0.707 0" size="0.08 0.2" />

            <!-- TODO 将hinge_z放置到蛇的第一段的1/2处，使其以第一段中部为z轴转动位  -->
            <joint pos=".3 0 0" axis="1 0 0" name="slider_x" type="slide"/>
            <joint pos=".3 0 0" axis="0 1 0" name="slider_y" type="slide"/>
            <joint pos=".3 0 0" axis="0 0 1" name="slider_z" type="slide"/>
            <!--<joint pos=".01 0 0" axis="1 0 0" name="hinge_x" type="hinge"/>-->
            <joint pos=".3 0 0" axis="0 1 0" name="hinge_y" type="hinge"/>
            <joint pos=".3 0 0" axis="0 0 1" name="hinge_z"  type="hinge"/>

            <body name="Module_1" pos="0.4 0 .04">
            <inertial pos="0.1 0 .04" quat="0.707 0 -0.707 0" mass="0.34605" diaginertia="0.003 0.003 0.001" />
            <joint name="Joint_1" type="hinge" pos="0.0 0 .04" axis="0 0 1"/>
            <geom type="capsule" pos="0.2 0 0" quat="0.707 0 -0.707 0" size="0.08 0.2" />
                <body name="Module_2" pos="0.4 0 0">
                    <joint name="Joint_2" type="hinge" pos="0 0 0" axis="0 0 1"/>
                    <geom type="capsule" pos="0.2 0 0" quat="0.707 0 -0.707 0" size="0.08 0.2" />
                    <body name="Module_3" pos="0.4 0 0">
                        <joint name="Joint_3" type="hinge" pos="0 0 0" axis="0 0 1"/>
                        <geom type="capsule" pos="0.2 0 0" quat="0.707 0 -0.707 0" size="0.08 0.2" />
                        <body name="Module_4" pos="0.4 0 0">
                            <joint name="Joint_4" type="hinge" pos="0 0 0" axis="0 0 1"/>
                            <geom type="capsule" pos="0.2 0 0" quat="0.707 0 -0.707 0" size="0.08 0.2" />
                            <body name="Module_5" pos="0.4 0 0">
                                <joint name="Joint_5" type="hinge" pos="0 0 0" axis="0 0 1"/>
                                <geom type="capsule" pos="0.2 0 0" quat="0.707 0 -0.707 0" size="0.08 0.2" />
                                <body name="Module_6" pos="0.4 0 0">
                                    <joint name="Joint_6" type="hinge" pos="0 0 0" axis="0 0 1"/>
                                    <geom type="capsule" pos="0.2 0 0" quat="0.707 0 -0.707 0" size="0.08 0.2" />
                                </body>
                            </body>
                        </body>
                    </body>
                </body>
            </body>
        </body>
    </worldbody>



    <actuator >
        <!--
        <motor joint="joint01"/>
        <motor joint="joint02"/>
        <motor joint="joint03"/>
        <motor joint="joint04"/>
        <motor joint="joint05"/>
        <motor joint="joint06"/>
        <motor joint="joint07"/>
        -->
<!--        <motor ctrllimited="true" ctrlrange="-1 1" gear="30.0" name="actuator_joint01" joint="Joint_1"/>-->
<!--        <motor ctrllimited="true" ctrlrange="-1 1" gear="30.0" name="actuator_joint02" joint="Joint_2"/>-->
<!--        <motor ctrllimited="true" ctrlrange="-1 1" gear="30.0" name="actuator_joint03" joint="Joint_3"/>-->
<!--        <motor ctrllimited="true" ctrlrange="-1 1" gear="30.0" name="actuator_joint04" joint="Joint_4"/>-->
<!--        <motor ctrllimited="true" ctrlrange="-1 1" gear="30.0" name="actuator_joint05" joint="Joint_5"/>-->
<!--        <motor ctrllimited="true" ctrlrange="-1 1" gear="30.0" name="actuator_joint06" joint="Joint_6"/>-->

        <position name="actuator_joint01" joint="Joint_1"/>
        <position name="actuator_joint02" joint="Joint_2"/>
        <position name="actuator_joint03" joint="Joint_3"/>
        <position name="actuator_joint04" joint="Joint_4"/>
        <position name="actuator_joint05" joint="Joint_5"/>
        <position name="actuator_joint06" joint="Joint_6"/>
    </actuator>
    <sensor>
        <!--
        <jointpos name="sensor_jointpos_joint01" joint="joint01" />
        <jointvel name="sensor_jointvel_joint01" joint="joint01" />
        -->

        <actuatorfrc name="sensor_actuatorfrc_joint01" actuator="actuator_joint01" />
        <actuatorfrc name="sensor_actuatorfrc_joint02" actuator="actuator_joint02" />
        <actuatorfrc name="sensor_actuatorfrc_joint03" actuator="actuator_joint03" />
        <actuatorfrc name="sensor_actuatorfrc_joint04" actuator="actuator_joint04" />
        <actuatorfrc name="sensor_actuatorfrc_joint05" actuator="actuator_joint05" />
        <actuatorfrc name="sensor_actuatorfrc_joint06" actuator="actuator_joint06" />

        <velocimeter name="sensor_velocimeter" site="site_head"/>
        <accelerometer name="sensor_accelerometer" site="site_head"/>

    </sensor>
</mujoco>
